Workbook

Sheet Result
A2: Current Ratio | B2: ONGC | C2: BPCL | D2: CIL | E2: NTPC | F2: IOCL | H2: Quick Ratio | I2: ONGC | J2: BPCL | K2: CIL | L2: NTPC | M2: IOCL
A3: Mar '23 | B3: {=TRANSPOSE('ONGC P&L and Balance Sheet'!$R$3:$V$3)} -> 0.64258428 | C3: {=TRANSPOSE('BPCL P&L and Balance Sheet'!$R$3:$V$3)} -> 0.66922418 | D3: {=TRANSPOSE('CIL P&L and Balance Sheet'!$R$3:$V$3)} -> 0.18939073 | E3: {=TRANSPOSE('NTPC P&L and Balance Sheet'!$R$3:$V$3)} -> 0.85520236 | F3: {=TRANSPOSE('IOCL P&L and Balance Sheet'!$R$3:$V$3)} -> 0.91561449 | H3: Mar '23 | I3: {=TRANSPOSE('ONGC P&L and Balance Sheet'!$R4:$V4)} -> 0.50961234 | J3: {=TRANSPOSE('BPCL P&L and Balance Sheet'!$R4:$V4)} -> 0.12615347 | K3: {=TRANSPOSE('CIL P&L and Balance Sheet'!$R4:$V4)} -> 0.18614474 | L3: {=TRANSPOSE('NTPC P&L and Balance Sheet'!$R4:$V4)} -> 0.57773221 | M3: {=TRANSPOSE('IOCL P&L and Balance Sheet'!$R4:$V4)} -> 0.11474809
A4: Mar '22 | B4: 0.33041051 | C4: 0.63650877 | D4: 0.11196742 | E4: 0.72446863 | F4: 0.89904044 | H4: Mar '22 | I4: 0.19979205 | J4: 0.14355173 | K4: 0.10968368 | L4: 0.52371031 | M4: 0.13989884
A5: Mar '21 | B5: 0.24755815 | C5: 0.67885881 | D5: 0.045308673 | E5: 0.48458944 | F5: 0.79857306 | H5: Mar '21 | I5: 0.1209816 | J5: 0.24261831 | K5: 0.045122417 | L5: 0.30821463 | M5: 0.1290161
A6: Mar '20 | B6: 0.24112212 | C6: 0.49763855 | D6: 0.21249335 | E6: 0.62134165 | F6: 0.81970725 | H6: Mar '20 | I6: 0.096797992 | J6: 0.10223621 | K6: 0.20958485 | L6: 0.3882635 | M6: 0.14279827
A7: Mar '19 | B7: 0.31833971 | C7: 0.58465045 | D7: 0.059994305 | E7: 0.45461406 | F7: 0.77157688 | H7: Mar '19 | I7: 0.17056277 | J7: 0.13972843 | K7: 0.053525137 | L7: 0.25901872 | M7: 0.13779864
A9: Return on Assests | B9: ONGC | C9: BPCL | D9: CIL | E9: NTPC | F9: IOCL | H9: Return on Equity | I9: ONGC | J9: BPCL | K9: CIL | L9: NTPC | M9: IOCL
A10: Mar '23 | B10: {=TRANSPOSE('ONGC P&L and Balance Sheet'!$R14:$V14)} -> 0.15268631 | C10: {=TRANSPOSE('BPCL P&L and Balance Sheet'!$R14:$V14)} -> 0.0231385 | D10: {=TRANSPOSE('CIL P&L and Balance Sheet'!$R14:$V14)} -> 0.89424216 | E10: {=TRANSPOSE('NTPC P&L and Balance Sheet'!$R14:$V14)} -> 0.055242935 | F10: {=TRANSPOSE('IOCL P&L and Balance Sheet'!$R14:$V14)} -> 0.032362881 | H10: Mar '23 | I10: {=TRANSPOSE('BPCL P&L and Balance Sheet'!$R16:$V16)} -> 0.03678905 | J10: {=TRANSPOSE('ONGC P&L and Balance Sheet'!$R16:$V16)} -> 0.15688625 | K10: {=TRANSPOSE('CIL P&L and Balance Sheet'!$R16:$V16)} -> 0.89536238 | L10: {=TRANSPOSE('NTPC P&L and Balance Sheet'!$R16:$V16)} -> 0.030876342 | M10: {=TRANSPOSE('IOCL P&L and Balance Sheet'!$R16:$V16)} -> 0.061958346
A11: Mar '22 | B11: 0.17405942 | C11: 0.11749398 | D11: 0.67663455 | E11: 0.055387307 | F11: 0.10768453 | H11: Mar '22 | I11: 0.16866644 | J11: 0.18250003 | K11: 0.67663455 | L11: 0.031401587 | M11: 0.20004516
A12: Mar '21 | B12: 0.052569618 | C12: 0.25866953 | D12: 0.45524193 | E12: 0.049421108 | F12: 0.1055936 | H12: Mar '21 | I12: 0.43395401 | J12: 0.056387737 | K12: 0.45524193 | L12: 0 | M12: 0.213797
A13: Mar '20 | B13: 0.062117664 | C13: 0.039643901 | D13: 0.73227052 | E13: 0.039138787 | F13: 0.0065921393 | H13: Mar '20 | I13: 0.07671511 | J13: 0.067674318 | K13: 0.73227052 | L13: 0.0044776482 | M13: 0.01297489
A14: Mar '19 | B14: 0.11895565 | C14: 0.11153017 | D14: 0.74797301 | E14: 0.020290043 | F14: 0.088028226 | H14: Mar '19 | I14: 0.19413365 | J14: 0.13160971 | K14: 0.74797301 | L14: 0.091660625 | M14: 0.15548074
A16: Earning per share | B16: ONGC | C16: BPCL | D16: CIL | E16: NTPC | F16: IOCL | H16: Price-Earning Ratio | I16: ONGC | J16: BPCL | K16: CIL | L16: NTPC | M16: IOCL
A17: Mar '23 | B17: {=TRANSPOSE('ONGC P&L and Balance Sheet'!$C40:$G40)} -> 30.86 | C17: {=TRANSPOSE('BPCL P&L and Balance Sheet'!$C40:$G40)} -> 8.78 | D17: {=TRANSPOSE('CIL P&L and Balance Sheet'!$C40:$G40)} -> 24.02 | E17: {=TRANSPOSE('NTPC P&L and Balance Sheet'!$C40:$G40)} -> 143.23 | F17: {=TRANSPOSE('IOCL P&L and Balance Sheet'!$C40:$G40)} -> 5.98 | H17: Mar '23 | I17: {=TRANSPOSE('BPCL P&L and Balance Sheet'!$R19:$V19)} -> 39.214123 | J17: {=TRANSPOSE('ONGC P&L and Balance Sheet'!$R19:$V19)} -> 5.0064809 | K17: {=TRANSPOSE('CIL P&L and Balance Sheet'!$R19:$V19)} -> 8.9092423 | L17: {=TRANSPOSE('NTPC P&L and Balance Sheet'!$R19:$V19)} -> 9.8702764 | M17: {=TRANSPOSE('IOCL P&L and Balance Sheet'!$R19:$V19)} -> 12.91806
A18: Mar '22 | B18: 32.04 | C18: 41.27 | D18: 18.18 | E18: 132.06 | F18: 26.34 | H18: Mar '22 | I18: 8.6988127 | J18: 5.1154806 | K18: 10.066007 | L18: 8.3032491 | M18: 3.0144267
A19: Mar '21 | B19: 8.94 | C19: 90.98 | D19: 12.4 | E19: 122.71 | F19: 23.78 | H19: Mar '21 | I19: 4.6933392 | J19: 11.521253 | K19: 10.564516 | L19: 7.5352113 | M19: 2.579058
A20: Mar '20 | B20: 10.69 | C20: 13.64 | D20: 18.31 | E20: 114.78 | F20: 1.43 | H20: Mar '20 | I20: 23.167155 | J20: 6.2675398 | K20: 7.5368651 | L20: 8.2191781 | M20: 38.062937
A21: Mar '19 | B21: 21.24 | C21: 36.26 | D21: 16.99 | E21: 108.55 | F21: 18.4 | H21: Mar '19 | I21: 10.976282 | J21: 7.5564972 | K21: 14.00824 | L21: 11.447811 | M21: 5.9092391
A23: Profit Margin | B23: ONGC | C23: BPCL | D23: CIL | E23: NTPC | F23: IOCL | H23: Total Assets Turnover | I23: ONGC | J23: BPCL | K23: CIL | L23: NTPC | M23: IOCL
A24: Mar '23 | B24: {=TRANSPOSE('BPCL P&L and Balance Sheet'!$R12:$V12)} -> 0.003952658 | C24: {=TRANSPOSE('ONGC P&L and Balance Sheet'!$R12:$V12)} -> 0.26868689 | D24: {=TRANSPOSE('CIL P&L and Balance Sheet'!$R12:$V12)} -> 7.5889434 | E24: {=TRANSPOSE('NTPC P&L and Balance Sheet'!$R12:$V12)} -> 0.10500552 | F24: {=TRANSPOSE('IOCL P&L and Balance Sheet'!$R12:$V12)} -> 0.0098178594 | H24: Mar '23 | I24: {=TRANSPOSE('ONGC P&L and Balance Sheet'!$R5:$V5)} -> 0.56826855 | J24: {=TRANSPOSE('BPCL P&L and Balance Sheet'!$R5:$V5)} -> 5.8539091 | K24: {=TRANSPOSE('CIL P&L and Balance Sheet'!$R5:$V5)} -> 0.11783487 | L24: {=TRANSPOSE('NTPC P&L and Balance Sheet'!$R5:$V5)} -> 0.52609552 | M24: {=TRANSPOSE('IOCL P&L and Balance Sheet'!$R5:$V5)} -> 3.2963276
A25: Mar '22 | B25: 0.024259712 | C25: 0.36535672 | D25: 9.8960792 | E25: 0.13872732 | F25: 0.040430568 | H25: Mar '22 | I25: 0.47640952 | J25: 4.8431729 | K25: 0.068374003 | L25: 0.39925308 | M25: 2.6634435
A26: Mar '21 | B26: 0.081883765 | C26: 0.16517706 | D26: 11.932995 | E26: 0.13879624 | F26: 0.057758499 | H26: Mar '21 | I26: 0.31826223 | J26: 3.1589843 | K26: 0.038149847 | L26: 0.35606949 | M26: 1.8281915
A27: Mar '20 | B27: 0.0094351296 | C27: 0.13980578 | D27: 13.347626 | E27: 0.10350839 | F27: 0.002704009 | H27: Mar '20 | I27: 0.444314 | J27: 4.2017336 | K27: 0.054861478 | L27: 0.37812189 | M27: 2.4379132
A28: Mar '19 | B28: 0.023991317 | C28: 0.24373626 | D28: 11.205897 | E28: 0.13010989 | F28: 0.03201461 | H28: Mar '19 | I28: 0.48805071 | J28: 4.6487724 | K28: 0.066748158 | L28: 0.37223423 | M28: 2.7496267
A30: Debt Ratio | B30: ONGC | C30: BPCL | D30: CIL | E30: NTPC | F30: IOCL | H30: Debt to Equity | I30: ONGC | J30: BPCL | K30: CIL | L30: NTPC | M30: IOCL
A31: Mar '23 | B31: {=TRANSPOSE('ONGC P&L and Balance Sheet'!$R8:$V8)} -> 0.027234405 | C31: {=TRANSPOSE('BPCL P&L and Balance Sheet'!$R8:$V8)} -> 0.4081313 | D31: {=TRANSPOSE('CIL P&L and Balance Sheet'!$R8:$V8)} -> 0.0024731503 | E31: {=TRANSPOSE('NTPC P&L and Balance Sheet'!$R8:$V8)} -> 0.57117867 | F31: {=TRANSPOSE('IOCL P&L and Balance Sheet'!$R8:$V8)} -> 0.49576789 | H31: Mar '23 | I31: {=TRANSPOSE('ONGC P&L and Balance Sheet'!$R9:$V9)} -> 0.027996884 | J31: {=TRANSPOSE('BPCL P&L and Balance Sheet'!$R9:$V9)} -> 0.68956392 | K31: {=TRANSPOSE('CIL P&L and Balance Sheet'!$R9:$V9)} -> 0.002479282 | L31: {=TRANSPOSE('NTPC P&L and Balance Sheet'!$R9:$V9)} -> 1.3319736 | M31: {=TRANSPOSE('IOCL P&L and Balance Sheet'!$R9:$V9)} -> 0.98321363
A32: Mar '22 | B32: 0.026265784 | C32: 0.32690272 | D32: 0 | E32: 0.57130277 | F32: 0.45768455 | H32: Mar '22 | I32: 0.026974284 | J32: 0.48566935 | K32: 0 | L32: 1.3326486 | M32: 0.84394525
A33: Mar '21 | B33: 0.068415046 | C33: 0.28051173 | D33: 0 | E33: 0.57966775 | F33: 0.4663918 | H33: Mar '21 | I33: 0.073439407 | J33: 0.38987672 | K33: 0 | L33: 1.3790703 | M33: 0.87403416
A34: Mar '20 | B34: 0.066970558 | C34: 0.53492711 | D34: 0 | E34: 0.58575111 | F34: 0.54592575 | H34: Mar '20 | I34: 0.07177754 | J34: 1.1502006 | K34: 0 | L34: 1.4140077 | M34: 1.202283
A35: Mar '19 | B35: 0.09614828 | C35: 0.42549799 | D35: 0 | E35: 0.55727898 | F35: 0.43383196 | H35: Mar '19 | I35: 0.10637617 | J35: 0.74063795 | K35: 0 | L35: 1.2587588 | M35: 0.76626006
A37: Interest Coverage Ratio | B37: ONGC | C37: BPCL | D37: CIL | E37: NTPC | F37: IOCL | H37: DuPont Analysis | I37: ONGC | J37: BPCL | K37: CIL | L37: NTPC | M37: IOCL
A38: Mar '23 | B38: {=TRANSPOSE('BPCL P&L and Balance Sheet'!$R11:$V11)} -> 1.6029479 | C38: {=TRANSPOSE('ONGC P&L and Balance Sheet'!$R11:$V11)} -> 19.654841 | D38: {=TRANSPOSE('CIL P&L and Balance Sheet'!$R11:$V11)} -> 7862.2031 | E38: {=TRANSPOSE('NTPC P&L and Balance Sheet'!$R11:$V11)} -> 3.3445396 | F38: {=TRANSPOSE('IOCL P&L and Balance Sheet'!$R11:$V11)} -> 2.389334 | H38: Mar '23 | I38: {=TRANSPOSE('ONGC P&L and Balance Sheet'!$R22:$V22)} -> 0.15688625 | J38: {=TRANSPOSE('BPCL P&L and Balance Sheet'!$R22:$V22)} -> 0.03678905 | K38: {=TRANSPOSE('CIL P&L and Balance Sheet'!$R22:$V22)} -> 0.89536238 | L38: {=TRANSPOSE('NTPC P&L and Balance Sheet'!$R22:$V22)} -> 0.12884295 | M38: {=TRANSPOSE('IOCL P&L and Balance Sheet'!$R22:$V22)} -> 0.061958346
A39: Mar '22 | B39: 7.3921676 | C39: 18.37937 | D39: 7572.2267 | E39: 3.7730961 | F39: 7.451902 | H39: Mar '22 | I39: 0.18250003 | J39: 0.16866644 | K39: 0.67663455 | L39: 0.13043754 | M39: 0.20004516
A40: Mar '21 | B40: 17.975827 | C40: 8.391815 | D40: 4831.0252 | E40: 3.0887327 | F40: 10.609954 | H40: Mar '21 | I40: 0.056387737 | J40: 0.43395401 | K40: 0.45524193 | L40: 0.11841951 | M40: 0.213797
A41: Mar '20 | B41: 2.1393857 | C41: 8.1118292 | D41: 2149.1483 | E41: 3.8028995 | F41: 0.36287618 | H41: Mar '20 | I41: 0.067674318 | J41: 0.07671511 | K41: 0.73227052 | L41: 0.091527915 | M41: 0.01297489
A42: Mar '19 | B42: 8.8103961 | C42: 16.913793 | D42: 586.5 | E42: 2.8330563 | F42: 6.8187997 | H42: Mar '19 | I42: 0.13160971 | J42: 0.19413365 | K42: 0.74797301 | L42: 0.10939475 | M42: 0.15548074

Sheet Graphs

Sheet ONGC P&L and Balance Sheet
B1: Oil and Natural Gas Corporation (ONGC) | P1: Oil and Natural Gas Corporation (ONGC)
P2: Financial Ratios | Q2: Formula | R2: Mar '23 | S2: Mar '22 | T2: Mar '21 | U2: Mar '20 | V2: Mar '19
B3: Profit & Loss account | C3: -- in Rs. Cr. -- | I3: Balance Sheet | J3: ---- in Rs. Cr. --- | P3: Current Ratio | Q3: Current Assets/Current Liabilities | R3: =J29/J32 -> 0.64258428 | S3: =K29/K32 -> 0.33041051 | T3: =L29/L32 -> 0.24755815 | U3: =M29/M32 -> 0.24112212 | V3: =N29/N32 -> 0.31833971
C4: Mar '23 | D4: Mar '22 | E4: Mar '21 | F4: Mar '20 | G4: Mar '19 | J4: Mar '23 | K4: Mar '22 | L4: Mar '21 | M4: Mar '20 | N4: Mar '19 | P4: Quick Ratio | Q4: (Current Assets - Inventory)/Current Liabilities | R4: =(J29-J26)/J32 -> 0.50961234 | S4: =(K29-K26)/K32 -> 0.19979205 | T4: =(L29-L26)/L32 -> 0.1209816 | U4: =(M29-M26)/M32 -> 0.096797992 | V4: =(N29-N26)/N32 -> 0.17056277
P5: Total asset turnover | Q5: Net Sales/Avg Total Assets | R5: =C11/((J36+K36)/2) -> 0.56826855 | S5: =D11/((K36+L36)/2) -> 0.47640952 | T5: =E11/((L36+M36)/2) -> 0.31826223 | U5: =F11/((M36+N36)/2) -> 0.444314 | V5: =G11/(N36) -> 0.48805071
C6: 12 mths | D6: 12 mths | E6: 12 mths | F6: 12 mths | G6: 12 mths | J6: 12 mths | K6: 12 mths | L6: 12 mths | M6: 12 mths | N6: 12 mths | P6: Receivables Turnover | Q6: Net Sales/Avg Accounts receivables | R6: =C11/((J27+K27)/2) -> 13.114463 | S6: =D11/((K27+L27)/2) -> 11.265183 | T6: =E11/((L27+M27)/2) -> 10.829216 | U6: =F11/((M27+N27)/2) -> 14.551455 | V6: =G11/(N27) -> 12.98696
P7: Inventory turnover | Q7: COGS/Avg Inventory | R7: =C21/((J26+K26)/2) -> 8.6770538 | S7: =D21/((K26+L26)/2) -> 6.7950188 | T7: =E21/((L26+M26)/2) -> 4.9393988 | U7: =F21/((M26+N26)/2) -> 6.7806229 | V7: =G21/(N26) -> 7.6227415
B8: Income | I8: Sources Of Funds | P8: Debt Ratio | Q8: Total Debt/Total Assets | R8: =J14/J36 -> 0.027234405 | S8: =K14/K36 -> 0.026265784 | T8: =L14/L36 -> 0.068415046 | U8: =M14/M36 -> 0.066970558 | V8: =N14/N36 -> 0.09614828
B9: Sales Turnover | C9: 155517.32 | D9: 110345.4 | E9: 68141.09 | F9: 96213.61 | G9: 109654.55 | I9: Total Share Capital | J9: 6290.14 | K9: 6290.14 | L9: 6290.14 | M9: 6290.15 | N9: 6290.15 | P9: Debt to Equity Ratio | Q9: Total Debt/Total share-holder equity | R9: =J14/(J15-J14) -> 0.027996884 | S9: =K14/(K15-K14) -> 0.026974284 | T9: =L14/(L15-L14) -> 0.073439407 | U9: =M14/(M15-M14) -> 0.07177754 | V9: =N14/(N15-N14) -> 0.10637617
B10: Excise Duty | C10: 11003.87 | D10: 26.53 | E10: 53.91 | F10: 47.77 | G10: 45.13 | I10: Equity Share Capital | J10: 6290.14 | K10: 6290.14 | L10: 6290.14 | M10: 6290.15 | N10: 6290.15 | P10: Equity Multiplier | Q10: Average total assets/ Average shareholder equity | R10: =AVERAGE(J36:K36)/AVERAGE(J12:K12) -> 1.027507 | S10: =AVERAGE(K36:L36)/AVERAGE(K12:L12) -> 1.0484927 | T10: =AVERAGE(L36:M36)/AVERAGE(L12:M12) -> 1.0726298 | U10: =AVERAGE(M36:N36)/AVERAGE(M12:N12) -> 1.0894537 | V10: =AVERAGE(N36:O36)/N12 -> 1.1063762
B11: Net Sales | C11: 144513.45 | D11: 110318.87 | E11: 68087.18 | F11: 96165.84 | G11: 109609.42 | I11: Reserves | J11: 251555.7 | K11: 230857.95 | L11: 198268.43 | M11: 188047.94 | N11: 196702.4 | P11: Interest coverage | Q11: EBIT/Intrest expenses | R11: =(C27-C30)/C28 -> 19.654841 | S11: =(D27-D30)/D28 -> 18.37937 | T11: =(E27-E30)/E28 -> 8.391815 | U11: =(F27-F30)/F28 -> 8.1118292 | V11: =(G27-G30)/G28 -> 16.913793
B12: Other Income | C12: -1643.27 | D12: 6488.48 | E12: 8484.23 | F12: 918.83 | G12: 7224.39 | I12: Networth | J12: 257845.84 | K12: 237148.09 | L12: 204558.57 | M12: 194338.09 | N12: 202992.55 | P12: Net profit margin | Q12: Net profit/ Sales | R12: =C34/C11 -> 0.26868689 | S12: =D34/D11 -> 0.36535672 | T12: =E34/E11 -> 0.16517706 | U12: =F34/F11 -> 0.13980578 | V12: =G34/G11 -> 0.24373626
B13: Stock Adjustments | C13: 481.67 | D13: 142.95 | E13: 426.35 | F13: -246.99 | G13: 166.27 | I13: Secured Loans | J13: 7218.88 | K13: 6396.9 | L13: 15022.66 | M13: 13949.11 | N13: 21593.57 | P13: Gross profit margin | Q13: Gross Profit/ Sales | R13: =(C14-C21)/C11 -> 0.50618437 | S13: =(D14-D21)/D11 -> 0.55701223 | T13: =(E14-E21)/E11 -> 0.51274542 | U13: =(F14-F21)/F11 -> 0.43177567 | V13: =(G14-G21)/G11 -> 0.52851443
B14: Total Income | C14: 143351.85 | D14: 116950.3 | E14: 76997.76 | F14: 96837.68 | G14: 117000.08 | I14: Total Debt | J14: 7218.88 | K14: 6396.9 | L14: 15022.66 | M14: 13949.11 | N14: 21593.57 | P14: Net return on assets | Q14: Net Income/ Average total assets | R14: =C34/AVERAGE(J36:K36) -> 0.15268631 | S14: =D34/AVERAGE(K36:L36) -> 0.17405942 | T14: =E34/AVERAGE(L36:M36) -> 0.052569618 | U14: =F34/AVERAGE(M36:N36) -> 0.062117664 | V14: =G34/N36 -> 0.11895565
B15: Expenditure | I15: Total Liabilities | J15: 265064.72 | K15: 243544.99 | L15: 219581.23 | M15: 208287.2 | N15: 224586.12 | P15: Gross return on assets | Q15: Gross Profit/Avg Total Assets | R15: =C26/((J36+K36)/2) -> 0.29411047 | S15: =D26/((K36+L36)/2) -> 0.23734558 | T15: =E26/((L36+M36)/2) -> 0.12352938 | U15: =F26/((M36+N36)/2) -> 0.18759871 | V15: =G26/(N36) -> 0.22577427
B16: Raw Materials | C16: 3921.31 | D16: 3272.47 | E16: 6664.78 | F16: 7654.91 | G16: 7423.12 | J16: Mar '23 | K16: Mar '22 | L16: Mar '21 | M16: Mar '20 | N16: Mar '19 | P16: Return on equity | Q16: Net Income/Average total shareholders' equity | R16: =C34/((J12+K12)/2) -> 0.15688625 | S16: =D34/((K12+L12)/2) -> 0.18250003 | T16: =E34/((L12+M12)/2) -> 0.056387737 | U16: =F34/((M12+N12)/2) -> 0.067674318 | V16: =G34/(N12) -> 0.13160971
B17: Power & Fuel Cost | C17: 682.01 | D17: 394.66 | E17: 506.49 | F17: 536.75 | G17: 535.01 | P17: Payout ratio | Q17: Total Dividends/Net Income | R17: =C36/C14 -> 0.12286183 | S17: =D36/D14 -> 0.097888847 | T17: =E36/E14 -> 0.02859239 | U17: =F36/F14 -> 0.074698919 | V17: =G36/G14 -> 0.082010029
B18: Employee Cost | C18: 10620.71 | D18: 11082.09 | E18: 10126.54 | F18: 11512.42 | G18: 12113.03 | J18: 12 mths | K18: 12 mths | L18: 12 mths | M18: 12 mths | N18: 12 mths | P18: Retention ratio | Q18: (Net Income - Dividend)/Net Income | R18: =(C34-C36)/C34 -> 0.54640787 | S18: =(D34-D36)/D34 -> 0.71596775 | T18: =(E34-E36)/E34 -> 0.80424472 | U18: =(F34-F36)/F34 -> 0.46196225 | V18: =(G34-G36)/G34 -> 0.64084236
B19: Other Manufacturing Expenses | C19: 9994.45 | D19: 5508.29 | E19: 5607.37 | F19: 6305.1 | G19: 5666.51 | P19: P/E ratio | Q19: Share Price/Earnings per share | R19: =C44/C40 -> 5.0064809 | S19: =D44/D40 -> 5.1154806 | T19: =E44/E40 -> 11.521253 | U19: =F44/F40 -> 6.2675398 | V19: =G44/G40 -> 7.5564972
B20: Miscellaneous Expenses | C20: 44982.92 | D20: 35243.83 | E20: 19181.19 | F20: 29306.43 | G20: 33332.25 | I20: Application Of Funds | P20: Dividend Yield | Q20: DPS/price per share | R20: =C36/C39/C44*100 -> 0.090615295 | S20: =D36/D39/D44*100 -> 0.055522029 | T20: =E36/E39/E44*100 -> 0.0169903 | U20: =F36/F39/F44*100 -> 0.085821009 | V20: =G36/G39/G44*100 -> 0.047521246
B21: Total Expenses | C21: 70201.4 | D21: 55501.34 | E21: 42086.37 | F21: 55315.61 | G21: 59069.92 | I21: Gross Block | J21: 156101.46 | K21: 227459.13 | L21: 225291.19 | M21: 208314 | N21: 181369.8 | P21: Market to book value | Q21: Market value of equity/Book value of equity | R21: =C44/C42 -> 0.75380562 | S21: =D44/D42 -> 0.8694499 | T21: =E44/E42 -> 0.63345633 | U21: =F44/F42 -> 0.4337131 | V21: =G44/G42 -> 0.9946703
C22: Mar '23 | D22: Mar '22 | E22: Mar '21 | F22: Mar '20 | G22: Mar '19 | I22: Less: Accum. Depreciation | J22: 14486.66 | K22: 90523.54 | L22: 94591.43 | M22: 80614.94 | N22: 56950.68 | P22: Du pont analysis | Q22: Asset Turnover x Net Profit Margin x Equity Multiplier | R22: =R12*R5*R10 -> 0.15688625 | S22: =S12*S5*S10 -> 0.18250003 | T22: =T12*T5*T10 -> 0.056387737 | U22: =U12*U5*U10 -> 0.067674318 | V22: =V12*V5*V10 -> 0.13160971
I23: Net Block | J23: 141614.8 | K23: 136935.59 | L23: 130699.76 | M23: 127699.06 | N23: 124419.12
C24: 12 mths | D24: 12 mths | E24: 12 mths | F24: 12 mths | G24: 12 mths | I24: Capital Work in Progress | J24: 46368.24 | K24: 41970.71 | L24: 40949.08 | M24: 36225.54 | N24: 35050.23
I25: Investments | J25: 84985.58 | K25: 85173.22 | L25: 81376.44 | M25: 72429.99 | N25: 84881.54
B26: Operating Profit | C26: 74793.72 | D26: 54960.48 | E26: 26427.16 | F26: 40603.24 | G26: 50705.77 | I26: Inventories | J26: 8319.51 | K26: 7861.42 | L26: 8474.47 | M26: 8566.62 | N26: 7749.17
B27: PBDIT | C27: 73150.45 | D27: 61448.96 | E27: 34911.39 | F27: 41522.07 | G27: 57930.16 | I27: Sundry Debtors | J27: 10250.31 | K27: 11788.48 | L27: 7797.33 | M27: 4777.39 | N27: 8439.96
B28: Interest | C28: 2699.6 | D28: 2359.86 | E28: 2214.54 | F28: 2823.68 | G28: 2492.14 | I28: Cash and Bank Balance | J28: 21634.05 | K28: 236.23 | L28: 302.55 | M28: 968.23 | N28: 504.06
B29: PBDT | C29: 70450.85 | D29: 59089.1 | E29: 32696.85 | F29: 38698.39 | G29: 55438.02 | I29: Total Current Assets | J29: 40203.87 | K29: 19886.13 | L29: 16574.35 | M29: 14312.24 | N29: 16693.19
B30: Depreciation | C30: 20090.24 | D30: 18076.22 | E30: 16327.38 | F30: 18616.86 | G30: 15778.62 | I30: Loans and Advances | J30: 53864.61 | K30: 53298.59 | L30: 48853.95 | M30: 46013.92 | N30: 41190.74
B31: Profit Before Tax | C31: 50360.61 | D31: 41012.88 | E31: 16369.47 | F31: 20081.53 | G31: 39659.4 | I31: Total CA, Loans & Advances | J31: 94068.48 | K31: 73184.72 | L31: 65428.3 | M31: 60326.16 | N31: 57883.93
B32: PBT (Post Extra-ord Items) | C32: 50360.61 | D32: 41012.88 | E32: 16369.47 | F32: 20081.53 | G32: 39659.4 | I32: Current Liabilities | J32: 62565.91 | K32: 60186.13 | L32: 66951.34 | M32: 59356.81 | N32: 52438.29
B33: Tax | C33: 11566.46 | D33: 734.25 | E33: 5156.35 | F33: 6924.15 | G33: 13238.24 | I33: Provisions | J33: 39406.47 | K33: 33533.12 | L33: 31921.01 | M33: 29036.74 | N33: 25210.4
B34: Reported Net Profit | C34: 38828.87 | D34: 40305.74 | E34: 11246.44 | F34: 13444.54 | G34: 26715.79 | I34: Total CL & Provisions | J34: 101972.38 | K34: 93719.25 | L34: 98872.35 | M34: 88393.55 | N34: 77648.69
B35: Total Value Addition | C35: 66280.08 | D35: 52228.87 | E35: 35421.59 | F35: 47660.7 | G35: 51646.8 | I35: Net Current Assets | J35: -7903.9 | K35: -20534.53 | L35: -33444.05 | M35: -28067.39 | N35: -19764.76
B36: Equity Dividend | C36: 17612.47 | D36: 11448.13 | E36: 2201.55 | F36: 7233.67 | G36: 9595.18 | I36: Total Assets | J36: 265064.72 | K36: 243544.99 | L36: 219581.23 | M36: 208287.2 | N36: 224586.13
B37: Corporate Dividend Tax | C37: 0 | D37: 0 | E37: 0 | F37: 1201.45 | G37: 1684.46
B38: Per share data (annualised) | I38: Contingent Liabilities | J38: 76267.04 | K38: 84271.41 | L38: 91576.91 | M38: 95668.02 | N38: 93825.42
B39: Shares in issue (lakhs) | C39: 125802.79 | D39: 125802.79 | E39: 125802.79 | F39: 125802.79 | G39: 125802.79 | I39: Book Value (Rs) | J39: 204.96 | K39: 188.51 | L39: 162.6 | M39: 154.48 | N39: 161.36
B40: Earning Per Share (Rs) | C40: 30.86 | D40: 32.04 | E40: 8.94 | F40: 10.69 | G40: 21.24
...

Sheet BPCL P&L and Balance Sheet
B1: Bharat Petroleum Corporation Limited (BPCL) | P1: Bharat Petroleum Corporation Limited (BPCL)
P2: Financial Ratios | Q2: Formula | R2: Mar '23 | S2: Mar '22 | T2: Mar '21 | U2: Mar '20 | V2: Mar '19
B3: Profit & Loss account | C3: --- in Rs. Cr. --- | I3: Balance Sheet | J3: -- in Rs. Cr. -- | P3: Current Ratio | Q3: Current Assets/Current Liabilities | R3: =J29/J32 -> 0.66922418 | S3: =K29/K32 -> 0.63650877 | T3: =L29/L32 -> 0.67885881 | U3: =M29/M32 -> 0.49763855 | V3: =N29/N32 -> 0.58465045
C4: Mar '23 | D4: Mar '22 | E4: Mar '21 | F4: Mar '20 | G4: Mar '19 | J4: Mar '23 | K4: Mar '22 | L4: Mar '21 | M4: Mar '20 | N4: Mar '19 | P4: Quick Ratio | Q4: (Current Assets - Inventory)/Current Liabilities | R4: =(J29-J26)/J32 -> 0.12615347 | S4: =(K29-K26)/K32 -> 0.14355173 | T4: =(L29-L26)/L32 -> 0.24261831 | U4: =(M29-M26)/M32 -> 0.10223621 | V4: =(N29-N26)/N32 -> 0.13972843
P5: Total asset turnover | Q5: Net Sales/Avg Total Assets | R5: =C11/((J36+K36)/2) -> 5.8539091 | S5: =D11/((K36+L36)/2) -> 4.8431729 | T5: =E11/((L36+M36)/2) -> 3.1589843 | U5: =F11/((M36+N36)/2) -> 4.2017336 | V5: =G11/(N36) -> 4.6487724
C6: 12 mths | D6: 12 mths | E6: 12 mths | F6: 12 mths | G6: 12 mths | J6: 12 mths | K6: 12 mths | L6: 12 mths | M6: 12 mths | N6: 12 mths | P6: Receivables Turnover | Q6: Net Sales/Avg Accounts receivables | R6: =C11/((J27+K27)/2) -> 57.487181 | S6: =D11/((K27+L27)/2) -> 41.247991 | T6: =E11/((L27+M27)/2) -> 35.798726 | U6: =F11/((M27+N27)/2) -> 48.057712 | V6: =G11/(N27) -> 44.564162
P7: Inventory turnover | Q7: COGS/Avg Inventory | R7: =C21/((J26+K26)/2) -> 12.454815 | S7: =D21/((K26+L26)/2) -> 11.111687 | T7: =E21/((L26+M26)/2) -> 9.2860631 | U7: =F21/((M26+N26)/2) -> 13.258456 | V7: =G21/(N26) -> 13.321815
B8: Income | I8: Sources Of Funds | P8: Debt Ratio | Q8: Total Debt/Total Assets | R8: =J14/J36 -> 0.4081313 | S8: =K14/K36 -> 0.32690272 | T8: =L14/L36 -> 0.28051173 | U8: =M14/M36 -> 0.53492711 | V8: =N14/N36 -> 0.42549799
B9: Sales Turnover | C9: 533467.55 | D9: 433406.48 | E9: 301864.98 | F9: 327580.78 | G9: 337622.53 | I9: Total Share Capital | J9: 2129.45 | K9: 2129.45 | L9: 2092.91 | M9: 1966.88 | N9: 1966.88 | P9: Debt to Equity Ratio | Q9: Total Debt/Total share-holder equity | R9: =J14/(J15-J14) -> 0.68956392 | S9: =K14/(K15-K14) -> 0.48566935 | T9: =L14/(L15-L14) -> 0.38987672 | U9: =M14/(M15-M14) -> 1.1502006 | V9: =N14/(N15-N14) -> 0.74063795
B10: Excise Duty | C10: 60342.88 | D10: 71129.71 | E10: 69319.86 | F10: 43197.83 | G10: 40347.48 | I10: Equity Share Capital | J10: 2129.45 | K10: 2129.45 | L10: 2092.91 | M10: 1966.88 | N10: 1966.88 | P10: Equity Multiplier | Q10: Average total assets/ Average shareholder equity | R10: =AVERAGE(J36:K36)/AVERAGE(J12:K12) -> 1.5899496 | S10: =AVERAGE(K36:L36)/AVERAGE(K12:L12) -> 1.4355326 | T10: =AVERAGE(L36:M36)/AVERAGE(L12:M12) -> 1.6776387 | U10: =AVERAGE(M36:N36)/AVERAGE(M12:N12) -> 1.935105 | V10: =AVERAGE(N36:O36)/N12 -> 1.7406379
B11: Net Sales | C11: 473124.67 | D11: 362276.77 | E11: 232545.12 | F11: 284382.95 | G11: 297275.05 | I11: Reserves | J11: 49866.89 | K11: 47540.33 | L11: 51595.15 | M11: 31247.5 | N11: 34770.8 | P11: Interest coverage | Q11: EBIT/Intrest expenses | R11: =(C27-C30)/C28 -> 1.6029479 | S11: =(D27-D30)/D28 -> 7.3921676 | T11: =(E27-E30)/E28 -> 17.975827 | U11: =(F27-F30)/F28 -> 2.1393857 | V11: =(G27-G30)/G28 -> 8.8103961
B12: Other Income | C12: 546.7 | D12: 2314.42 | E12: 10725.79 | F12: 1815.42 | G12: 2845.58 | I12: Networth | J12: 51996.34 | K12: 49669.78 | L12: 54544.55 | M12: 33214.38 | N12: 36737.68 | P12: Net profit margin | Q12: Net profit/ Sales | R12: =C34/C11 -> 0.003952658 | S12: =D34/D11 -> 0.024259712 | T12: =E34/E11 -> 0.081883765 | U12: =F34/F11 -> 0.0094351296 | V12: =G34/G11 -> 0.023991317
B13: Stock Adjustments | C13: 975.21 | D13: 4288.73 | E13: 3633.57 | F13: 456.62 | G13: 1703.06 | I13: Secured Loans | J13: 35854.8 | K13: 24123.09 | L13: 21265.65 | M13: 38203.2 | N13: 27209.32 | P13: Gross profit margin | Q13: Gross Profit/ Sales | R13: =(C14-C21)/C11 -> 0.024313528 | S13: =(D14-D21)/D11 -> 0.051085942 | T13: =(E14-E21)/E11 -> 0.11978931 | U13: =(F14-F21)/F11 -> 0.029730088 | V13: =(G14-G21)/G11 -> 0.049818644
B14: Total Income | C14: 474646.58 | D14: 368879.92 | E14: 246904.48 | F14: 286654.99 | G14: 301823.69 | I14: Total Debt | J14: 35854.8 | K14: 24123.09 | L14: 21265.65 | M14: 38203.2 | N14: 27209.32 | P14: Net return on assets | Q14: Net Income/ Average total assets | R14: =C34/AVERAGE(J36:K36) -> 0.0231385 | S14: =D34/AVERAGE(K36:L36) -> 0.11749398 | T14: =E34/AVERAGE(L36:M36) -> 0.25866953 | U14: =F34/AVERAGE(M36:N36) -> 0.039643901 | V14: =G34/N36 -> 0.11153017
B15: Expenditure | I15: Total Liabilities | J15: 87851.14 | K15: 73792.87 | L15: 75810.2 | M15: 71417.58 | N15: 63947 | P15: Gross return on assets | Q15: Gross Profit/Avg Total Assets | R15: =C26/((J36+K36)/2) -> 0.13556494 | S15: =D26/((K36+L36)/2) -> 0.21647724 | T15: =E26/((L36+M36)/2) -> 0.23270921 | U15: =F26/((M36+N36)/2) -> 0.098095233 | V15: =G26/(N36) -> 0.1870965
B16: Raw Materials | C16: 434402.3 | D16: 328004.78 | E16: 199115.07 | F16: 256571.42 | G16: 266603.82 | J16: Mar '23 | K16: Mar '22 | L16: Mar '21 | M16: Mar '20 | N16: Mar '19 | P16: Return on equity | Q16: Net Income/Average total shareholders' equity | R16: =C34/((J12+K12)/2) -> 0.03678905 | S16: =D34/((K12+L12)/2) -> 0.16866644 | T16: =E34/((L12+M12)/2) -> 0.43395401 | U16: =F34/((M12+N12)/2) -> 0.07671511 | V16: =G34/(N12) -> 0.19413365
B17: Power & Fuel Cost | C17: 4020.86 | D17: 2974.12 | E17: 2331.58 | F17: 2764.43 | G17: 2178.63 | P17: Payout ratio | Q17: Total Dividends/Net Income | R17: =C36/C14 -> 0.0027421455 | S17: =D36/D14 -> 0.039988406 | T17: =E36/E14 -> 0.018450172 | U17: =F36/F14 -> 0.016810661 | V17: =G36/G14 -> 0.011729994
B18: Employee Cost | C18: 2763.97 | D18: 3314.45 | E18: 4477.17 | F18: 3691.45 | G18: 3664.18 | J18: 12 mths | K18: 12 mths | L18: 12 mths | M18: 12 mths | N18: 12 mths | P18: Retention ratio | Q18: (Net Income - Dividend)/Net Income | R18: =(C34-C36)/C34 -> 0.30402118 | S18: =(D34-D36)/D34 -> -0.67839039 | T18: =(E34-E36)/E34 -> 0.76076521 | U18: =(F34-F36)/F34 -> -0.79594438 | V18: =(G34-G36)/G34 -> 0.50359225
P19: P/E ratio | Q19: Share Price/Earnings per share | R19: =C44/C40 -> 39.214123 | S19: =D44/D40 -> 8.6988127 | T19: =E44/E40 -> 4.6933392 | U19: =F44/F40 -> 23.167155 | V19: =G44/G40 -> 10.976282
B20: Miscellaneous Expenses | C20: 21956.12 | D20: 16079.32 | E20: 13124.24 | F20: 15172.96 | G20: 14567.22 | I20: Application Of Funds | P20: Dividend Yield | Q20: DPS/price per share | R20: =C36/C39/C44*100 -> 0.01775233 | S20: =D36/D39/D44*100 -> 0.19295507 | T20: =E36/E39/E44*100 -> 0.050974189 | U20: =F36/F39/F44*100 -> 0.07753171 | V20: =G36/G39/G44*100 -> 0.045226207
B21: Total Expenses | C21: 463143.25 | D21: 350372.67 | E21: 219048.06 | F21: 278200.26 | G21: 287013.85 | I21: Gross Block | J21: 113490.42 | K21: 90369.26 | L21: 80439.44 | M21: 69654.44 | N21: 55694.18 | P21: Market to book value | Q21: Market value of equity/Book value of equity | R21: =C44/C42 -> 1.4100254 | S21: =D44/D42 -> 1.5391211 | T21: =E44/E42 -> 1.6645876 | U21: =F44/F42 -> 1.8712619 | V21: =G44/G42 -> 2.1308491
C22: Mar '23 | D22: Mar '22 | E22: Mar '21 | F22: Mar '20 | G22: Mar '19 | I22: Less: Accum. Depreciation | J22: 26894.19 | K22: 20874.61 | L22: 16503.19 | M22: 12703.32 | N22: 9206.06 | P22: Du pont analysis | Q22: Asset Turnover x Net Profit Margin x Equity Multiplier | R22: =R12*R5*R10 -> 0.03678905 | S22: =S12*S5*S10 -> 0.16866644 | T22: =T12*T5*T10 -> 0.43395401 | U22: =U12*U5*U10 -> 0.07671511 | V22: =V12*V5*V10 -> 0.19413365
C23: 12 mths | D23: 12 mths | E23: 12 mths | F23: 12 mths | G23: 12 mths | I23: Net Block | J23: 86596.23 | K23: 69494.65 | L23: 63936.25 | M23: 56951.12 | N23: 46488.12
I24: Capital Work in Progress | J24: 5673.38 | K24: 3329.96 | L24: 7452.38 | M24: 9504.71 | N24: 7065.73
I25: Investments | J25: 13872.35 | K25: 20236.82 | L25: 17684.09 | M25: 16058.02 | N25: 15991.62
B26: Operating Profit | C26: 10956.63 | D26: 16192.83 | E26: 17130.63 | F26: 6639.31 | G26: 11964.26 | I26: Inventories | J26: 38064.7 | K26: 36307.06 | L26: 26756.75 | M26: 20421.06 | N26: 21544.65
B27: PBDIT | C27: 11503.33 | D27: 18507.25 | E27: 27856.42 | F27: 8454.73 | G27: 14809.84 | I27: Sundry Debtors | J27: 6721.86 | K27: 9738.32 | L27: 7827.47 | M27: 5164.34 | N27: 6670.72
B28: Interest | C28: 3216.48 | D28: 1860.48 | E28: 1328.36 | F28: 2181.86 | G28: 1318.96 | I28: Cash and Bank Balance | J28: 2120.44 | K28: 834.49 | L28: 7053.49 | M28: 115.78 | N28: 95.41
B29: PBDT | C29: 8286.85 | D29: 16646.77 | E29: 26528.06 | F29: 6272.87 | G29: 13490.88 | I29: Total Current Assets | J29: 46907 | K29: 46879.87 | L29: 41637.71 | M29: 25701.18 | N29: 28310.78
B30: Depreciation | C30: 6347.48 | D30: 4754.27 | E30: 3978.05 | F30: 3786.89 | G30: 3189.28 | I30: Loans and Advances | J30: 7755.02 | K30: 10571.26 | L30: 9894.06 | M30: 18253.95 | N30: 17771
B31: Profit Before Tax | C31: 1939.37 | D31: 11892.5 | E31: 22550.01 | F31: 2485.98 | G31: 10301.6 | I31: Total CA, Loans & Advances | J31: 54662.02 | K31: 57451.13 | L31: 51531.77 | M31: 43955.13 | N31: 46081.78
B32: PBT (Post Extra-ord Items) | C32: 1939.37 | D32: 11892.5 | E32: 22550.01 | F32: 2485.98 | G32: 10301.6 | I32: Current Liabilities | J32: 70091.61 | K32: 73651.57 | L32: 61334.86 | M32: 51646.28 | N32: 48423.43
B33: Tax | C33: 346.6 | D33: 3124.71 | E33: 3575.91 | F33: -12.15 | G33: 3307.6 | I33: Provisions | J33: 2861.23 | K33: 3068.12 | L33: 3459.43 | M33: 3405.12 | N33: 3256.82
B34: Reported Net Profit | C34: 1870.1 | D34: 8788.73 | E34: 19041.67 | F34: 2683.19 | G34: 7132.02 | I34: Total CL & Provisions | J34: 72952.84 | K34: 76719.69 | L34: 64794.29 | M34: 55051.4 | N34: 51680.25
B35: Total Value Addition | C35: 28740.95 | D35: 22367.89 | E35: 19932.99 | F35: 21628.84 | G35: 20410.03 | I35: Net Current Assets | J35: -18290.82 | K35: -19268.56 | L35: -13262.52 | M35: -11096.27 | N35: -5598.47
B36: Equity Dividend | C36: 1301.55 | D36: 14750.92 | E36: 4555.43 | F36: 4818.86 | G36: 3540.39 | I36: Total Assets | J36: 87851.14 | K36: 73792.87 | L36: 75810.2 | M36: 71417.58 | N36: 63947
B37: Corporate Dividend Tax | C37: 0 | D37: 0 | E37: 0 | F37: 923.43 | G37: 647.95
B38: Per share data (annualised) | I38: Contingent Liabilities | J38: 12223.06 | K38: 8516.7 | L38: 9852.33 | M38: 10828.22 | N38: 19102.49
B39: Shares in issue (lakhs) | C39: 21294.55 | D39: 21294.55 | E39: 20929.13 | F39: 19668.8 | G39: 19668.8 | I39: Book Value (Rs) | J39: 244.18 | K39: 233.25 | L39: 256.52 | M39: 168.87 | N39: 186.78
B40: Earning Per Share (Rs) | C40: 8.78 | D40: 41.27 | E40: 90.98 | F40: 13.64 | G40: 36.26
...

Sheet CIL P&L and Balance Sheet
B1: Coal India Limited (CIL) | P1: Coal India Limited (CIL)
P2: Financial Ratios | Q2: Formula | R2: Mar '23 | S2: Mar '22 | T2: Mar '21 | U2: Mar '20 | V2: Mar '19
B3: Profit & Loss account | C3: -- in Rs. Cr. - | I3: Balance Sheet | J3: -- in Rs. Cr. - | P3: Current Ratio | Q3: Current Assets/Current Liabilities | R3: =J29/J32 -> 0.18939073 | S3: =K29/K32 -> 0.11196742 | T3: =L29/L32 -> 0.045308673 | U3: =M29/M32 -> 0.21249335 | V3: =N29/N32 -> 0.059994305
C4: Mar '23 | D4: Mar '22 | E4: Mar '21 | F4: Mar '20 | G4: Mar '19 | J4: Mar '23 | K4: Mar '22 | L4: Mar '21 | M4: Mar '20 | N4: Mar '19 | P4: Quick Ratio | Q4: (Current Assets - Inventory)/Current Liabilities | R4: =(J29-J26)/J32 -> 0.18614474 | S4: =(K29-K26)/K32 -> 0.10968368 | T4: =(L29-L26)/L32 -> 0.045122417 | U4: =(M29-M26)/M32 -> 0.20958485 | V4: =(N29-N26)/N32 -> 0.053525137
P5: Total asset turnover | Q5: Net Sales/Avg Total Assets | R5: =C11/((J36+K36)/2) -> 0.11783487 | S5: =D11/((K36+L36)/2) -> 0.068374003 | T5: =E11/((L36+M36)/2) -> 0.038149847 | U5: =F11/((M36+N36)/2) -> 0.054861478 | V5: =G11/(N36) -> 0.066748158
C6: 12 mths | D6: 12 mths | E6: 12 mths | F6: 12 mths | G6: 12 mths | J6: 12 mths | K6: 12 mths | L6: 12 mths | M6: 12 mths | N6: 12 mths | P6: Receivables Turnover | Q6: Net Sales/Avg Accounts receivables | R6: =C11/((J27+K27)/2) -> 657.84486 | S6: =D11/((K27+L27)/2) -> 157.75888 | T6: =E11/((L27+M27)/2) -> 64.153307 | U6: =F11/((M27+N27)/2) -> 205.63504 | V6: =G11/(N27) -> 3737.2
P7: Inventory turnover | Q7: COGS/Avg Inventory | R7: =C21/((J26+K26)/2) -> 81.405518 | S7: =D21/((K26+L26)/2) -> 98.920904 | T7: =E21/((L26+M26)/2) -> 75.622028 | U7: =F21/((M26+N26)/2) -> 45.428258 | V7: =G21/(N26) -> 28.877079
B8: Income | I8: Sources Of Funds | P8: Debt Ratio | Q8: Total Debt/Total Assets | R8: =J14/J36 -> 0.0024731503 | S8: =K14/K36 -> 0 | T8: =L14/L36 -> 0 | U8: =M14/M36 -> 0 | V8: =N14/N36 -> 0
B9: Sales Turnover | C9: 1950.51 | D9: 1131.92 | E9: 640.25 | F9: 845.16 | G9: 934.3 | I9: Total Share Capital | J9: 6162.73 | K9: 6162.73 | L9: 6162.73 | M9: 6162.73 | N9: 6162.73 | P9: Debt to Equity Ratio | Q9: Total Debt/Total share-holder equity | R9: =J14/(J15-J14) -> 0.002479282 | S9: =K14/(K15-K14) -> 0 | T9: =L14/(L15-L14) -> 0 | U9: =M14/(M15-M14) -> 0 | V9: =N14/(N15-N14) -> 0
B10: Excise Duty | C10: 0 | D10: 0 | E10: 0 | F10: 0 | G10: 0 | I10: Equity Share Capital | J10: 6162.73 | K10: 6162.73 | L10: 6162.73 | M10: 6162.73 | N10: 6162.73 | P10: Equity Multiplier | Q10: Average total assets/ Average shareholder equity | R10: =AVERAGE(J36:K36)/AVERAGE(J12:K12) -> 1.0012527 | S10: =AVERAGE(K36:L36)/AVERAGE(K12:L12) -> 1 | T10: =AVERAGE(L36:M36)/AVERAGE(L12:M12) -> 1 | U10: =AVERAGE(M36:N36)/AVERAGE(M12:N12) -> 1 | V10: =AVERAGE(N36:O36)/N12 -> 1
B11: Net Sales | C11: 1950.51 | D11: 1131.92 | E11: 640.25 | F11: 845.16 | G11: 934.3 | I11: Reserves | J11: 10543.72 | K11: 10195.22 | L11: 10588.98 | M11: 10650.57 | N11: 7834.66 | P11: Interest coverage | Q11: EBIT/Intrest expenses | R11: =(C27-C30)/C28 -> 7862.2031 | S11: =(D27-D30)/D28 -> 7572.2267 | T11: =(E27-E30)/E28 -> 4831.0252 | U11: =(F27-F30)/F28 -> 2149.1483 | V11: =(G27-G30)/G28 -> 586.5
B12: Other Income | C12: 14552.63 | D12: 10935.62 | E12: 7679.18 | F12: 11566.33 | G12: 10548.66 | I12: Networth | J12: 16706.45 | K12: 16357.95 | L12: 16751.71 | M12: 16813.3 | N12: 13997.39 | P12: Net profit margin | Q12: Net profit/ Sales | R12: =C34/C11 -> 7.5889434 | S12: =D34/D11 -> 9.8960792 | T12: =E34/E11 -> 11.932995 | U12: =F34/F11 -> 13.347626 | V12: =G34/G11 -> 11.205897
B13: Stock Adjustments | C13: 7.32 | D13: 11.99 | E13: -14.21 | F13: -15.68 | G13: 9.41 | I13: Secured Loans | J13: 41.42 | K13: 0 | L13: 0 | M13: 0 | N13: 0 | P13: Gross profit margin | Q13: Gross Profit/ Sales | R13: =(C14-C21)/C11 -> 7.7612368 | S13: =(D14-D21)/D11 -> 10.052981 | T13: =(E14-E21)/E11 -> 12.028114 | U13: =(F14-F21)/F11 -> 13.439952 | V13: =(G14-G21)/G11 -> 11.352574
B14: Total Income | C14: 16510.46 | D14: 12079.53 | E14: 8305.22 | F14: 12395.81 | G14: 11492.37 | I14: Total Debt | J14: 41.42 | K14: 0 | L14: 0 | M14: 0 | N14: 0 | P14: Net return on assets | Q14: Net Income/ Average total assets | R14: =C34/AVERAGE(J36:K36) -> 0.89424216 | S14: =D34/AVERAGE(K36:L36) -> 0.67663455 | T14: =E34/AVERAGE(L36:M36) -> 0.45524193 | U14: =F34/AVERAGE(M36:N36) -> 0.73227052 | V14: =G34/N36 -> 0.74797302
B15: Expenditure | I15: Total Liabilities | J15: 16747.87 | K15: 16357.95 | L15: 16751.71 | M15: 16813.3 | N15: 13997.39 | P15: Gross return on assets | Q15: Gross Profit/Avg Total Assets | R15: =C26/((J36+K36)/2) -> 0.035385923 | S15: =D26/((K36+L36)/2) -> 0.026792785 | T15: =E26/((L36+M36)/2) -> 0.0013001635 | U15: =F26/((M36+N36)/2) -> -0.013464158 | V15: =G26/(N36) -> 0.0041472017
B16: Raw Materials | C16: 474.61 | D16: 1.19 | E16: 2.24 | F16: 5.09 | G16: 6.11 | J16: Mar '23 | K16: Mar '22 | L16: Mar '21 | M16: Mar '20 | N16: Mar '19 | P16: Return on equity | Q16: Net Income/Average total shareholders' equity | R16: =C34/((J12+K12)/2) -> 0.89536238 | S16: =D34/((K12+L12)/2) -> 0.67663455 | T16: =E34/((L12+M12)/2) -> 0.45524193 | U16: =F34/((M12+N12)/2) -> 0.73227052 | V16: =G34/(N12) -> 0.74797302
B17: Power & Fuel Cost | C17: 7.4 | D17: 8.42 | E17: 8.47 | F17: 10.08 | G17: 12.28 | P17: Payout ratio | Q17: Total Dividends/Net Income | R17: =C36/C14 -> 0.86783712 | S17: =D36/D14 -> 0.89281537 | T17: =E36/E14 -> 0.92754075 | U17: =F36/F14 -> 0.59659433 | V17: =G36/G14 -> 0.705301
B18: Employee Cost | C18: 421.48 | D18: 438.84 | E18: 443.9 | F18: 545.25 | G18: 474.66 | J18: 12 mths | K18: 12 mths | L18: 12 mths | M18: 12 mths | N18: 12 mths | P18: Retention ratio | Q18: (Net Income - Dividend)/Net Income | R18: =(C34-C36)/C34 -> 0.032016624 | S18: =(D34-D36)/D34 -> 0.037207284 | T18: =(E34-E36)/E34 -> -0.0082891585 | U18: =(F34-F36)/F34 -> 0.3444421 | V18: =(G34-G36)/G34 -> 0.22580368
B19: Other Manufacturing Expenses | C19: 0 | D19: 25.78 | E19: 12.75 | F19: 73.07 | G19: 151.62 | P19: P/E ratio | Q19: Share Price/Earnings per share | R19: =C44/C40 -> 8.9092423 | S19: =D44/D40 -> 10.066007 | T19: =E44/E40 -> 10.564516 | U19: =F44/F40 -> 7.5368651 | V19: =G44/G40 -> 14.00824
B20: Miscellaneous Expenses | C20: 462.71 | D20: 219.36 | E20: 134.49 | F20: 396.47 | G20: 235.76 | I20: Application Of Funds | P20: Dividend Yield | Q20: DPS/price per share | R20: =C36/C39/C44*100 -> 0.10864522 | S20: =D36/D39/D44*100 -> 0.095628557 | T20: =E36/E39/E44*100 -> 0.095420095 | U20: =F36/F39/F44*100 -> 0.086956479 | V20: =G36/G39/G44*100 -> 0.05526296
B21: Total Expenses | C21: 1372.09 | D21: 700.36 | E21: 604.22 | F21: 1036.9 | G21: 885.66 | I21: Gross Block | J21: 717.63 | K21: 568.39 | L21: 484.15 | M21: 419.77 | N21: 356.21 | P21: Market to book value | Q21: Market value of equity/Book value of equity | R21: =C44/C42 -> 7.8937661 | S21: =D44/D42 -> 6.8952524 | T21: =E44/E42 -> 4.8197204 | U21: =F44/F42 -> 5.058651 | V21: =G44/G42 -> 10.479965
C22: Mar '23 | D22: Mar '22 | E22: Mar '21 | F22: Mar '20 | G22: Mar '19 | I22: Less: Accum. Depreciation | J22: 163.89 | K22: 145.51 | L22: 133.93 | M22: 117.18 | N22: 63.78 | P22: Du pont analysis | Q22: Asset Turnover x Net Profit Margin x Equity Multiplier | R22: =R12*R5*R10 -> 0.89536238 | S22: =S12*S5*S10 -> 0.67663455 | T22: =T12*T5*T10 -> 0.45524193 | U22: =U12*U5*U10 -> 0.73227052 | V22: =V12*V5*V10 -> 0.74797302
I23: Net Block | J23: 553.74 | K23: 422.88 | L23: 350.22 | M23: 302.59 | N23: 292.43
C24: 12 mths | D24: 12 mths | E24: 12 mths | F24: 12 mths | G24: 12 mths | I24: Capital Work in Progress | J24: 108.73 | K24: 160.72 | L24: 173.97 | M24: 193.81 | N24: 189.65
I25: Investments | J25: 13862.67 | K25: 13565.04 | L25: 13224.87 | M25: 12326.56 | N25: 12537.9
B26: Operating Profit | C26: 585.74 | D26: 443.55 | E26: 21.82 | F26: -207.42 | G26: 58.05 | I26: Inventories | J26: 20.55 | K26: 13.16 | L26: 1 | M26: 14.98 | N26: 30.67
B27: PBDIT | C27: 15138.37 | D27: 11379.17 | E27: 7701 | F27: 11358.91 | G27: 10606.71 | I27: Sundry Debtors | J27: 3.57 | K27: 2.36 | L27: 11.99 | M27: 7.97 | N27: 0.25
B28: Interest | C28: 1.92 | D28: 1.5 | E28: 1.59 | F28: 5.26 | G28: 18.04 | I28: Cash and Bank Balance | J28: 1174.89 | K28: 629.69 | L28: 230.27 | M28: 1071.48 | N28: 253.51
B29: PBDT | C29: 15136.45 | D29: 11377.67 | E29: 7699.41 | F29: 11353.65 | G29: 10588.67 | I29: Total Current Assets | J29: 1199.01 | K29: 645.21 | L29: 243.26 | M29: 1094.43 | N29: 284.43
B30: Depreciation | C30: 42.94 | D30: 20.83 | E30: 19.67 | F30: 54.39 | G30: 26.25 | I30: Loans and Advances | J30: 7706.53 | K30: 7646.45 | L30: 8506.22 | M30: 8481.09 | N30: 5736.16
B31: Other Written Off | C31: 0 | D31: 0 | E31: 5.76 | F31: 0 | G31: 0 | I31: Total CA, Loans & Advances | J31: 8905.54 | K31: 8291.66 | L31: 8749.48 | M31: 9575.52 | N31: 6020.59
B32: Profit Before Tax | C32: 15093.51 | D32: 11356.84 | E32: 7673.98 | F32: 11299.26 | G32: 10562.42 | I32: Current Liabilities | J32: 6330.88 | K32: 5762.48 | L32: 5368.95 | M32: 5150.42 | N32: 4740.95
B33: Tax | C33: 291.2 | D33: 155.27 | E33: 33.88 | F33: 18.38 | G33: 92.75 | I33: Provisions | J33: 351.93 | K33: 319.87 | L33: 377.88 | M33: 434.76 | N33: 302.23
B34: Reported Net Profit | C34: 14802.31 | D34: 11201.57 | E34: 7640.1 | F34: 11280.88 | G34: 10469.67 | I34: Total CL & Provisions | J34: 6682.81 | K34: 6082.35 | L34: 5746.83 | M34: 5585.18 | N34: 5043.18
B35: Total Value Addition | C35: 897.48 | D35: 699.17 | E35: 601.98 | F35: 1031.81 | G35: 879.55 | I35: Net Current Assets | J35: 2222.73 | K35: 2209.31 | L35: 3002.65 | M35: 3990.34 | N35: 977.41
B36: Equity Dividend | C36: 14328.39 | D36: 10784.79 | E36: 7703.43 | F36: 7395.27 | G36: 8105.58 | I36: Total Assets | J36: 16747.87 | K36: 16357.95 | L36: 16751.71 | M36: 16813.3 | N36: 13997.39
B38: Per share data (annualised) | I38: Contingent Liabilities | J38: 1388.48 | K38: 1108.49 | L38: 1791.95 | M38: 1681.87 | N38: 1657.69
B39: Shares in issue (lakhs) | C39: 61627.28 | D39: 61627.28 | E39: 61627.28 | F39: 61627.28 | G39: 61627.28 | I39: Book Value (Rs) | J39: 27.11 | K39: 26.54 | L39: 27.18 | M39: 27.28 | N39: 22.71
B40: Earning Per Share (Rs) | C40: 24.02 | D40: 18.18 | E40: 12.4 | F40: 18.31 | G40: 16.99
B41: Equity Dividend (%) | C41: 242.5 | D41: 170 | E41: 160 | F41: 120 | G41: 131
...

Sheet NTPC P&L and Balance Sheet
B1: National Thermal Power Corporation (NTPC) | P1: National Thermal Power Corporation (NTPC)
P2: Financial Ratios | Q2: Formula | R2: Mar '23 | S2: Mar '22 | T2: Mar '21 | U2: Mar '20 | V2: Mar '19
B3: Profit & Loss account | C3: -- in Rs. Cr. - | I3: Balance Sheet | J3: -- in Rs. Cr. -- | P3: Current Ratio | Q3: Current Assets/Current Liabilities | R3: =J29/J32 -> 0.85520236 | S3: =K29/K32 -> 0.72446863 | T3: =L29/L32 -> 0.48458944 | U3: =M29/M32 -> 0.62134165 | V3: =N29/N32 -> 0.45461406
C4: Mar '23 | D4: Mar '22 | E4: Mar '21 | F4: Mar '20 | G4: Mar '19 | J4: Mar '23 | K4: Mar '22 | L4: Mar '21 | M4: Mar '20 | N4: Mar '19 | P4: Quick Ratio | Q4: (Current Assets - Inventory)/Current Liabilities | R4: =(J29-J26)/J32 -> 0.57773221 | S4: =(K29-K26)/K32 -> 0.52371031 | T4: =(L29-L26)/L32 -> 0.30821463 | U4: =(M29-M26)/M32 -> 0.3882635 | V4: =(N29-N26)/N32 -> 0.25901872
P5: Total asset turnover | Q5: Net Sales/Avg Total Assets | R5: =C10/((J36+K36)/2) -> 0.52609552 | S5: =D10/((K36+L36)/2) -> 0.39925308 | T5: =E10/((L36+M36)/2) -> 0.35606949 | U5: =F10/((M36+N36)/2) -> 0.37812189 | V5: =G10/N36 -> 0.37223423
C6: 12 mths | D6: 12 mths | E6: 12 mths | F6: 12 mths | G6: 12 mths | J6: 12 mths | K6: 12 mths | L6: 12 mths | M6: 12 mths | N6: 12 mths | P6: Receivables Turnover | Q6: Net Sales/Avg Accounts receivables | R6: =C10/((J27+K27)/2) -> 6.9637747 | S6: =D10/((K27+L27)/2) -> 6.452963 | T6: =E10/((L27+M27)/2) -> 6.7556891 | U6: =F10/((M27+N27)/2) -> 8.1072535 | V6: =G10/((N27+O27)/2) -> 21.415444
P7: Inventory turnover | Q7: COGS/Avg Inventory | R7: =C19/((J26+K26)/2) -> 10.406318 | S7: =D19/((K26+L26)/2) -> 8.8172044 | T7: =E19/((L26+M26)/2) -> 7.0718766 | U7: =F19/((M26+N26)/2) -> 7.5436028 | V7: =G19/N26 -> 8.4546533
B8: Income | I8: Sources Of Funds | P8: Debt Ratio | Q8: Total Debt/Total Assets | R8: =J14/J36 -> 0.57117867 | S8: =K14/K36 -> 0.57130277 | T8: =L14/L36 -> 0.57966775 | U8: =M14/M36 -> 0.58575111 | V8: =N14/N36 -> 0.55727898
B9: Sales Turnover | C9: 163769.77 | D9: 116137.33 | E9: 99206.72 | F9: 97700.39 | G9: 90307.43 | I9: Total Share Capital | J9: 9696.67 | K9: 9696.67 | L9: 9696.67 | M9: 9894.56 | N9: 9894.56 | P9: Debt to Equity Ratio | Q9: Total Debt/Total share-holder equity | R9: =J14/(J15-J14) -> 1.3319736 | S9: =K14/(K15-K14) -> 1.3326486 | T9: =L14/(L15-L14) -> 1.3790703 | U9: =M14/(M15-M14) -> 1.4140077 | V9: =N14/(N15-N14) -> 1.2587588
B10: Net Sales | C10: 163769.77 | D10: 116137.33 | E10: 99206.72 | F10: 97700.39 | G10: 90307.43 | I10: Equity Share Capital | J10: 9696.67 | K10: 9696.67 | L10: 9696.67 | M10: 9894.56 | N10: 9894.56 | P10: Equity Multiplier | Q10: Average total assets/ Average shareholder equity | R10: =AVERAGE(J36:K36)/AVERAGE(J12:K12) -> 2.3322974 | S10: =AVERAGE(K36:L36)/AVERAGE(K12:L12) -> 2.3550077 | T10: =AVERAGE(L36:M36)/AVERAGE(L12:M12) -> 2.3961322 | U10: =AVERAGE(M36:N36)/AVERAGE(M12:N12) -> 2.3385476 | V10: =AVERAGE(N36:O36)/AVERAGE(N12:O12) -> 2.2587588
B11: Other Income | C11: 3284.25 | D11: 5124.13 | E11: 4647.39 | F11: 7321.28 | G11: -2154.34 | I11: Reserves | J11: 129193.21 | K11: 118354.4 | L11: 109288.82 | M11: 103674.88 | N11: 97513.61 | P11: Interest coverage | Q11: EBIT/Intrest expenses | R11: =(C25-C28)/C26 -> 3.3445396 | S11: =(D25-D28)/D26 -> 3.7730961 | T11: =(E25-E28)/E26 -> 3.0887327 | U11: =(F25-F28)/F26 -> 3.8028995 | V11: =(G25-G28)/G26 -> 2.8330563
B12: Total Income | C12: 167054.02 | D12: 121261.46 | E12: 103854.11 | F12: 105021.67 | G12: 88153.09 | I12: Networth | J12: 138889.88 | K12: 128051.07 | L12: 118985.49 | M12: 113569.44 | N12: 107408.17 | P12: Net profit margin | Q12: Net profit/ Sales | R12: =C32/C10 -> 0.10500552 | S12: =D32/D10 -> 0.13872732 | T12: =E32/E10 -> 0.13879624 | U12: =F32/F10 -> 0.10350839 | V12: =G32/G10 -> 0.13010989
B13: Expenditure | I13: Secured Loans | J13: 184997.65 | K13: 170647.08 | L13: 164089.36 | M13: 160588.06 | N13: 135200.98 | P13: Gross profit margin | Q13: Gross Profit/ Sales | R13: =(C12-C19)/C10 -> 0.28401237 | S13: =(D12-D19)/D10 -> 0.33554956 | T13: =(E12-E19)/E10 -> 0.3371823 | U13: =(F12-F19)/F10 -> 0.35224015 | V13: =(G12-G19)/G10 -> 0.2282996
B14: Raw Materials | C14: 248.6 | D14: 143.45 | E14: 90.9 | F14: 78.86 | G14: 86.31 | I14: Total Debt | J14: 184997.65 | K14: 170647.08 | L14: 164089.36 | M14: 160588.06 | N14: 135200.98 | P14: Net return on assets | Q14: Net Income/ Average total assets | R14: =C32/AVERAGE(J36:K36) -> 0.055242935 | S14: =D32/AVERAGE(K36:L36) -> 0.055387307 | T14: =E32/AVERAGE(L36:M36) -> 0.049421108 | U14: =F32/AVERAGE(M36:N36) -> 0.039138787 | V14: =G34/N36 -> 0.020290043
B15: Power & Fuel Cost | C15: 101729.22 | D15: 67757.55 | E15: 56898.33 | F15: 58131.19 | G15: 56586.3 | I15: Total Liabilities | J15: 323887.53 | K15: 298698.15 | L15: 283074.85 | M15: 274157.5 | N15: 242609.15 | P15: Gross return on assets | Q15: Gross Profit/Avg Total Assets | R15: =C24/((J36+K36)/2) -> 0.13886728 | S15: =D24/((K36+L36)/2) -> 0.11635363 | T15: =E24/((L36+M36)/2) -> 0.10338007 | U15: =F24/((M36+N36)/2) -> 0.10485475 | V15: =G26/N36 -> 0.019441723
B16: Employee Cost | C16: 5559.03 | D16: 5289.51 | E16: 4942.19 | F16: 4925.6 | G16: 4779.89 | J16: Mar '23 | K16: Mar '22 | L16: Mar '21 | M16: Mar '20 | N16: Mar '19 | P16: Return on equity | Q16: Net Income/Average total shareholders' equity | R16: =C34/((J12+K12)/2) -> 0.030876342 | S16: =D34/((K12+L12)/2) -> 0.031401587 | T16: =E34/((L12+M12)/2) -> 0 | U16: =F34/((M12+N12)/2) -> 0.0044776482 | V16: =G34/((N12+O12)/2) -> 0.091660625
B17: Selling and Admin Expenses | C17: 39.85 | D17: 23.39 | E17: 7.43 | F17: 18.75 | G17: 20.52 | P17: Payout ratio | Q17: Total Dividends/Net Income | R17: =C36/C14 -> 0 | S17: 0.097888847 | T17: 0.028592028 | U17: 0.074698919 | V17: 0.082010029
B18: Miscellaneous Expenses | C18: 12964.68 | D18: 9077.73 | E18: 8464.51 | F18: 7453.27 | G18: 6062.92 | J18: 12 mths | K18: 12 mths | L18: 12 mths | M18: 12 mths | N18: 12 mths | P18: Retention ratio | Q18: (Net Income - Dividend)/Net Income | R18: =(C32-C34)/C32 -> 0.76035677 | S18: =(D32-D34)/D32 -> 0.75925958 | T18: =(E32-E34)/E32 -> 1 | U18: =(F32-F34)/F32 -> 0.95107888 | V18: =(G32-G34)/G32 -> 0.58105565
B19: Total Expenses | C19: 120541.38 | D19: 82291.63 | E19: 70403.36 | F19: 70607.67 | G19: 67535.94 | P19: P/E ratio | Q19: Share Price/Earnings per share | R19: =C42/C38 -> 9.8702764 | S19: =D42/D38 -> 8.3032491 | T19: =E42/E38 -> 7.5352113 | U19: =F42/F38 -> 8.2191781 | V19: =G42/G38 -> 11.447811
C20: Mar '23 | D20: Mar '22 | E20: Mar '21 | F20: Mar '20 | G20: Mar '19 | I20: Application Of Funds | P20: Dividend Yield | Q20: DPS/price per share | R20: =C34/C37/C42*100 -> 0.024285696 | S20: =D34/D37/D42*100 -> 0.028985534 | T20: =E34/E37/E42*100 -> 0 | U20: =F34/F37/F42*100 -> 0.0059524068 | V20: =G34/G37/G42*100 -> 0.036580941
I21: Gross Block | J21: 270085.4 | K21: 238876.32 | L21: 212114.11 | M21: 193436.3 | N21: 153305.99 | P21: Market to book value | Q21: Market value of equity/Book value of equity | R21: =C42/C40 -> 1.2218111 | S21: =D42/D40 -> 1.0449796 | T21: =E42/E40 -> 0.87197457 | U21: =F42/F40 -> 0.73183481 | V21: =G42/G40 -> 1.2528789
C22: 12 mths | D22: 12 mths | E22: 12 mths | F22: 12 mths | G22: 12 mths | I22: Less: Accum. Depreciation | J22: 72724.34 | K22: 58810.54 | L22: 47665.25 | M22: 36625 | N22: 27685.37 | P22: Du pont analysis | Q22: Asset Turnover x Net Profit Margin x Equity Multiplier | R22: =R12*R5*R10 -> 0.12884295 | S22: =S12*S5*S10 -> 0.13043754 | T22: =T12*T5*T10 -> 0.11841951 | U22: =U12*U5*U10 -> 0.091527915 | V22: =V12*V5*V10 -> 0.10939475
I23: Net Block | J23: 197361.06 | K23: 180065.78 | L23: 164448.86 | M23: 156811.3 | N23: 125620.62
B24: Operating Profit | C24: 43228.39 | D24: 33845.7 | E24: 28803.36 | F24: 27092.72 | G24: 22771.49 | I24: Capital Work in Progress | J24: 61788.8 | K24: 68697.13 | L24: 75438.5 | M24: 73359.28 | N24: 91206.69
B25: PBDIT | C25: 46512.64 | D25: 38969.83 | E25: 33450.75 | F25: 34414 | G25: 20617.15 | I25: Investments | J25: 29769.75 | K25: 29881.07 | L25: 28625.64 | M25: 26400.89 | N25: 13145.94
B26: Interest | C26: 9979.23 | D26: 7350.91 | E26: 7459.03 | F26: 6781.97 | G26: 4716.74 | I26: Inventories | J26: 13679.75 | K26: 9487.21 | L26: 9178.94 | M26: 10731.86 | N26: 7988.02
B27: PBDT | C27: 36533.41 | D27: 31618.92 | E27: 25991.72 | F27: 27632.03 | G27: 15900.41 | I27: Sundry Debtors | J27: 24741.45 | K27: 22293.32 | L27: 13701.72 | M27: 15668.11 | N27: 8433.86
B28: Depreciation | C28: 13136.71 | D28: 11234.14 | E28: 10411.8 | F28: 8622.85 | G28: 7254.36 | I28: Cash and Bank Balance | J28: 3741.73 | K28: 2455.59 | L28: 2338.46 | M28: 2209.11 | N28: 2144.34
B29: Profit Before Tax | C29: 23396.7 | D29: 20384.78 | E29: 15579.92 | F29: 19009.18 | G29: 8646.05 | I29: Total Current Assets | J29: 42162.93 | K29: 34236.12 | L29: 25219.12 | M29: 28609.08 | N29: 18566.22
B30: PBT (Post Extra-ord Items) | C30: 23396.7 | D30: 20384.78 | E30: 15579.92 | F30: 19009.18 | G30: 8646.05 | I30: Loans and Advances | J30: 51304.72 | K30: 41616.7 | L30: 49487.27 | M30: 42486.9 | N30: 42338.3
B31: Tax | C31: 6279.27 | D31: 4366.39 | E31: 1925.39 | F31: 9181.95 | G31: -2918.71 | I31: Total CA, Loans & Advances | J31: 93467.65 | K31: 75852.82 | L31: 74706.39 | M31: 71095.98 | N31: 60904.52
B32: Reported Net Profit | C32: 17196.73 | D32: 16111.42 | E32: 13769.52 | F32: 10112.81 | G32: 11749.89 | I32: Current Liabilities | J32: 49301.7 | K32: 47256.87 | L32: 52042.24 | M32: 46044.04 | N32: 40839.52
B33: Total Value Addition | C33: 120292.78 | D33: 82148.18 | E33: 70312.46 | F33: 70528.81 | G33: 67449.63 | I33: Provisions | J33: 9198.03 | K33: 8541.78 | L33: 8102.3 | M33: 7465.91 | N33: 7429.1
B34: Equity Dividend | C34: 4121.08 | D34: 3878.67 | E34: 0 | F34: 494.73 | G34: 4922.55 | I34: Total CL & Provisions | J34: 58499.73 | K34: 55798.65 | L34: 60144.54 | M34: 53509.95 | N34: 48268.62
B35: Corporate Dividend Tax | C35: 0 | D35: 0 | E35: 0 | F35: 101.18 | G35: 1000.49 | I35: Net Current Assets | J35: 34967.92 | K35: 20054.17 | L35: 14561.85 | M35: 17586.03 | N35: 12635.9
B36: Per share data (annualised) | I36: Total Assets | J36: 323887.53 | K36: 298698.15 | L36: 283074.85 | M36: 274157.5 | N36: 242609.15
B37: Shares in issue (lakhs) | C37: 96966.66 | D37: 96966.66 | E37: 96966.66 | F37: 98945.57 | G37: 98945.57
B38: Earning Per Share (Rs) | C38: 17.73 | D38: 16.62 | E38: 14.2 | F38: 10.22 | G38: 11.88 | I38: Contingent Liabilities | J38: 65555.58 | K38: 67976.31 | L38: 127550.29 | M38: 112448.68 | N38: 97370.02
B39: Equity Dividend (%) | C39: 72.5 | D39: 70 | E39: 61.5 | F39: 31.5 | G39: 60.8 | I39: Book Value (Rs) | J39: 143.23 | K39: 132.06 | L39: 122.71 | M39: 114.78 | N39: 108.55
B40: Book Value (Rs) | C40: 143.23 | D40: 132.06 | E40: 122.71 | F40: 114.78 | G40: 108.55
...

Sheet IOCL P&L and Balance Sheet
B1: Indian Oil Corporation Limited (IOCL) | P1: Indian Oil Corporation Limited (IOCL)
P2: Financial Ratios | Q2: Formula | R2: Mar '23 | S2: Mar '22 | T2: Mar '21 | U2: Mar '20 | V2: Mar '19
B3: Standalone Profit & Loss account | C3: ------------------- in Rs. Cr. ------------------- | I3: Standalone Balance Sheet | J3: ------------------- in Rs. Cr. ------------------- | P3: Current Ratio | Q3: Current Assets/Current Liabilities | R3: =J29/J32 -> 0.91561449 | S3: =K29/K32 -> 0.89904044 | T3: =L29/L32 -> 0.79857306 | U3: =M29/M32 -> 0.81970725 | V3: =N29/N32 -> 0.77157688
C4: Mar '23 | D4: Mar '22 | E4: Mar '21 | F4: Mar '20 | G4: Mar '19 | J4: Mar '23 | K4: Mar '22 | L4: Mar '21 | M4: Mar '20 | N4: Mar '19 | P4: Quick Ratio | Q4: (Current Assets - Inventory)/Current Liabilities | R4: =(J29-J26)/J32 -> 0.11474809 | S4: =(K29-K26)/K32 -> 0.13989884 | T4: =(L29-L26)/L32 -> 0.1290161 | U4: =(M29-M26)/M32 -> 0.14279827 | V4: =(N29-N26)/N32 -> 0.13779864
P5: Total asset turnover | Q5: Net Sales/Avg Total Assets | R5: =C11/((J36+K36)/2) -> 3.2963276 | S5: =D11/((K36+L36)/2) -> 2.6634435 | T5: =E11/((L36+M36)/2) -> 1.8281915 | U5: =F11/((M36+N36)/2) -> 2.4379132 | V5: =G11/(N36) -> 2.7496267
C6: 12 mths | D6: 12 mths | E6: 12 mths | F6: 12 mths | G6: 12 mths | J6: 12 mths | K6: 12 mths | L6: 12 mths | M6: 12 mths | N6: 12 mths | P6: Receivables Turnover | Q6: Net Sales/Avg Accounts receivables | R6: =C11/((J27+K27)/2) -> 49.855118 | S6: =D11/((K27+L27)/2) -> 37.937401 | T6: =E11/((L27+M27)/2) -> 28.813423 | U6: =F11/((M27+N27)/2) -> 34.331859 | V6: =G11/(N27) -> 34.159799
P7: Inventory turnover | Q7: COGS/Avg Inventory | R7: =C21/((J26+K26)/2) -> 7.594977 | S7: =D21/((K26+L26)/2) -> 6.2528417 | T7: =E21/((L26+M26)/2) -> 4.8713988 | U7: =F21/((M26+N26)/2) -> 7.0037208 | V7: =G21/(N26) -> 6.9523258
B8: Income | I8: Sources Of Funds | P8: Debt Ratio | Q8: Total Debt/Total Assets | R8: =J14/J36 -> 0.49576789 | S8: =K14/K36 -> 0.45768455 | T8: =L14/L36 -> 0.4663918 | U8: =M14/M36 -> 0.54592575 | V8: =N14/N36 -> 0.43383196
B9: Sales Turnover | C9: 934952.66 | D9: 728459.94 | E9: 514890.47 | F9: 566353.55 | G9: 605932.34 | I9: Total Share Capital | J9: 13771.56 | K9: 9181.04 | L9: 9181.04 | M9: 9181.04 | N9: 9181.04 | P9: Debt to Equity Ratio | Q9: Total Debt/Total share-holder equity | R9: =J14/(J15-J14) -> 0.98321363 | S9: =K14/(K15-K14) -> 0.84394525 | T9: =L14/(L15-L14) -> 0.87403416 | U9: =M14/(M15-M14) -> 1.202283 | V9: =N14/(N15-N14) -> 0.76626006
B10: Excise Duty | C10: 95480.46 | D10: 130296.19 | E10: 136832.86 | F10: 80693.19 | G10: 78231.08 | I10: Equity Share Capital | J10: 13771.56 | K10: 9181.04 | L10: 9181.04 | M10: 9181.04 | N10: 9181.04 | P10: Equity Multiplier | Q10: Average total assets/ Average shareholder equity | R10: =AVERAGE(J36:K36)/AVERAGE(J12:K12) -> 1.914488 | S10: =AVERAGE(K36:L36)/AVERAGE(K12:L12) -> 1.8576963 | T10: =AVERAGE(L36:M36)/AVERAGE(L12:M12) -> 2.0247156 | U10: =AVERAGE(M36:N36)/AVERAGE(M12:N12) -> 1.9682366 | V10: =AVERAGE(N36:O36)/N12 -> 1.7662601
B11: Net Sales | C11: 839472.2 | D11: 598163.75 | E11: 378057.61 | F11: 485660.36 | G11: 527701.26 | I11: Reserves | J11: 120985.98 | K11: 122105.32 | L11: 101319 | M11: 84587.83 | N11: 99476.47 | P11: Interest coverage | Q11: EBIT/Intrest expenses | R11: =(C27-C30)/C28 -> 2.389334 | S11: =(D27-D30)/D28 -> 7.451902 | T11: =(E27-E30)/E28 -> 10.609954 | U11: =(F27-F30)/F28 -> 0.36287618 | V11: =(G27-G30)/G28 -> 6.8187997
B12: Other Income | C12: 6165.54 | D12: 3748.07 | E12: 4567.5 | F12: -7865.46 | G12: 3086.61 | I12: Networth | J12: 134757.54 | K12: 131286.36 | L12: 110500.04 | M12: 93768.87 | N12: 108657.51 | P12: Net profit margin | Q12: Net profit/ Sales | R12: =C34/C11 -> 0.0098178594 | S12: =D34/D11 -> 0.040430568 | T12: =E34/E11 -> 0.057758499 | U12: =F34/F11 -> 0.002704009 | V12: =G34/G11 -> 0.03201461
B13: Stock Adjustments | C13: 7064.61 | D13: 12197.02 | E13: 5547.57 | F13: 6410.43 | G13: 3011.13 | I13: Secured Loans | J13: 132495.45 | K13: 110798.5 | L13: 96580.81 | M13: 112736.72 | N13: 83259.91 | P13: Gross profit margin | Q13: Gross Profit/ Sales | R13: =(C14-C21)/C11 -> 0.033852425 | S13: =(D14-D21)/D11 -> 0.078560244 | T13: =(E14-E21)/E11 -> 0.11276231 | U13: =(F14-F21)/F11 -> 0.022517588 | V13: =(G14-G21)/G11 -> 0.069951756
B14: Total Income | C14: 852702.35 | D14: 614108.84 | E14: 388172.68 | F14: 484205.33 | G14: 533799 | I14: Total Debt | J14: 132495.45 | K14: 110798.5 | L14: 96580.81 | M14: 112736.72 | N14: 83259.91 | P14: Net return on assets | Q14: Net Income/ Average total assets | R14: =C34/AVERAGE(J36:K36) -> 0.032362881 | S14: =D34/AVERAGE(K36:L36) -> 0.10768453 | T14: =E34/AVERAGE(L36:M36) -> 0.1055936 | U14: =F34/AVERAGE(M36:N36) -> 0.0065921393 | V14: =G34/N36 -> 0.088028226
B15: Expenditure | I15: Total Liabilities | J15: 267252.99 | K15: 242084.86 | L15: 207080.85 | M15: 206505.59 | N15: 191917.42 | P15: Gross return on assets | Q15: Gross Profit/Avg Total Assets | R15: =C26/((J36+K36)/2) -> 0.087378662 | S15: =D26/((K36+L36)/2) -> 0.19255174 | T15: =E26/((L36+M36)/2) -> 0.18406382 | U15: =F26/((M36+N36)/2) -> 0.094378886 | V15: =G26/(N36) -> 0.17625821
B16: Raw Materials | C16: 768014.64 | D16: 518224.18 | E16: 302449.22 | F16: 427926.57 | G16: 450911.97 | J16: Mar '23 | K16: Mar '22 | L16: Mar '21 | M16: Mar '20 | N16: Mar '19 | P16: Return on equity | Q16: Net Income/Average total shareholders' equity | R16: =C34/((J12+K12)/2) -> 0.061958346 | S16: =D34/((K12+L12)/2) -> 0.20004516 | T16: =E34/((L12+M12)/2) -> 0.213797 | U16: =F34/((M12+N12)/2) -> 0.01297489 | V16: =G34/(N12) -> 0.15548074
B17: Power & Fuel Cost | C17: 7804.41 | D17: 7544.71 | E17: 4360.08 | F17: 5185.81 | G17: 6272.73 | P17: Payout ratio | Q17: Total Dividends/Net Income | R17: =C36/C14 -> 0.003876335 | S17: =D36/D14 -> 0.015698846 | T17: =E36/E14 -> 0.024835519 | U17: =F36/F14 -> 0.0099551568 | V17: =G36/G14 -> 0.018118243
B18: Employee Cost | C18: 8769.85 | D18: 10991.7 | E18: 10712.04 | F18: 8792.65 | G18: 11102.17 | J18: 12 mths | K18: 12 mths | L18: 12 mths | M18: 12 mths | N18: 12 mths | P18: Retention ratio | Q18: (Net Income - Dividend)/Net Income | R18: =(C34-C36)/C34 -> 0.59895266 | S18: =(D34-D36)/D34 -> 0.60135792 | T18: =(E34-E36)/E34 -> 0.55850649 | U18: =(F34-F36)/F34 -> -2.6705984 | V18: =(G34-G36)/G34 -> 0.42752373
B19: Selling and Admin Expenses | C19: 81.06 | D19: 36.83 | E19: 65.03 | F19: 62.31 | G19: 79.7 | P19: P/E ratio | Q19: Share Price/Earnings per share | R19: =C44/C40 -> 12.91806 | S19: =D44/D40 -> 3.0144267 | T19: =E44/E40 -> 2.579058 | U19: =F44/F40 -> 38.062937 | V19: =G44/G40 -> 5.9092391
